Workbook

Sheet Construccion1 (ch)
A2: Descripción series | B2: 2002 | C2: 2003 | D2: 2004 | E2: 2005 | F2: 2006 | G2: 2007 | H2: 2008 | I2: 2009 | J2: 2010 | K2: 2011 | L2: 2012 | M2: 2013 | N2: 2014 | O2: 2015 | P2: 2016 | Q2: 2017 | R2: 2018 | S2: 2019 | T2: 2020 | U2: 2021 | V2: 2022 | W2: 2023 | X2: 2024
A3: IPV General. | B3: 82.4 | C3: 84.23 | D3: 89.13 | E3: 92.3 | F3: 94.79 | G3: 98.78 | H3: 100 | I3: 102.27 | J3: 108.77 | K3: 118.1 | L3: 126.74 | M3: 137.04 | N3: 148.27 | O3: 160.65 | P3: 165.03 | Q3: 174.68 | R3: 187.58 | S3: 198.33 | T3: 205.27 | U3: 219.6 | V3: 210.37 | W3: 210.99 | X3: 217.31
A4: IPV Casas | B4: 78.1 | C4: 80.96 | D4: 87.8 | E4: 91.02 | F4: 94.34 | G4: 98.51 | H4: 100 | I4: 102.31 | J4: 110.82 | K4: 122.58 | L4: 130.35 | M4: 140.16 | N4: 151.08 | O4: 161.84 | P4: 164.58 | Q4: 173.25 | R4: 189.31 | S4: 201.51 | T4: 207.46 | U4: 225.89 | V4: 212.01 | W4: 213.88 | X4: 221.63
A5: IPV Casas Nuevas | B5: 70.7 | C5: 74.87 | D5: 82.49 | E5: 85.98 | F5: 91.54 | G5: 95.92 | H5: 100 | I5: 102.89 | J5: 104.18 | K5: 118.54 | L5: 129.72 | M5: 135.89 | N5: 143.52 | O5: 157.52 | P5: 160.13 | Q5: 167.25 | R5: 175.71 | S5: 184.43 | T5: 195.66 | U5: 203.85 | V5: 211.14
A6: IPV Casas Usadas | B6: 85.3 | C6: 86.81 | D6: 92.76 | E6: 95.7 | F6: 96.81 | G6: 100.8 | H6: 100 | I6: 101.88 | J6: 115.64 | K6: 125.34 | L6: 131 | M6: 143.26 | N6: 156.33 | O6: 165.12 | P6: 167.95 | Q6: 177.56 | R6: 198.79 | S6: 213.03 | T6: 216.58 | U6: 240.72 | V6: 218.6 | W6: 216.65 | X6: 222.65
A7: IPV Departamentos | B7: 89.96 | C7: 89.88 | D7: 91.13 | E7: 94.21 | F7: 95.43 | G7: 99.15 | H7: 100 | I7: 102.23 | J7: 106.51 | K7: 112.96 | L7: 122.6 | M7: 133.61 | N7: 145.28 | O7: 159.42 | P7: 165.49 | Q7: 176.1 | R7: 186.31 | S7: 195.76 | T7: 203.51 | U7: 214.16 | V7: 209.18 | W7: 208.67 | X7: 213.68
A8: IPV Departamentos Nuevos | B8: 86.38 | C8: 86.95 | D8: 86.67 | E8: 90.8 | F8: 93.12 | G8: 98.09 | H8: 100 | I8: 100.06 | J8: 99.32 | K8: 104.61 | L8: 112.92 | M8: 118.8 | N8: 126.74 | O8: 141.06 | P8: 147.65 | Q8: 158.9 | R8: 166.15 | S8: 172.66 | T8: 181.67 | U8: 187.7 | V8: 194.13 | W8: 192.94 | X8: 199.91
A9: IPV Departamentos Usados | B9: 97.06 | C9: 96.04 | D9: 99.64 | E9: 100.95 | F9: 100.07 | G9: 101.43 | H9: 100 | I9: 106.64 | J9: 124.11 | K9: 133.5 | L9: 146.18 | M9: 165.58 | N9: 183.99 | O9: 197.72 | P9: 202.79 | Q9: 211.68 | R9: 229.43 | S9: 244.88 | T9: 249.79 | U9: 271.66 | V9: 248.43 | W9: 249.23 | X9: 250.41
A10: IPV Nuevas | B10: 77.08 | C10: 79.89 | D10: 84.52 | E10: 88.3 | F10: 92.36 | G10: 97.03 | H10: 100 | I10: 101.35 | J10: 101.39 | K10: 110.5 | L10: 119.97 | M10: 125.94 | N10: 133.71 | O10: 147.98 | P10: 153.18 | Q10: 163.11 | R10: 170.82 | S10: 178.11 | T10: 187.85 | U10: 194.72 | V10: 201.48 | W10: 203.82 | X10: 212.31
A11: IPV Usadas | B11: 88.9 | C11: 89.62 | D11: 94.86 | E11: 97.3 | F11: 97.79 | G11: 100.99 | H11: 100 | I11: 103.32 | J11: 118.2 | K11: 127.82 | L11: 135.66 | M11: 150.22 | N11: 165.02 | O11: 175.39 | P11: 178.96 | Q11: 188.31 | R11: 208.23 | S11: 222.79 | T11: 226.8 | U11: 249.96 | V11: 227.62 | W11: 226.63 | X11: 230.88
A13: El IPV (índice de precio de la vivienda) se elabora sobre la base de registros administrativos innominados del Servicio de Impuestos Internos, correspondientes a transacciones efectivas del valor de viviendas nuevas y usadas

Sheet Construccion2(Ch)
B2: Índice de Precios de Materiales e Insumos de Construcción (IPMIC) | C2: 2019 | D2: 2020 | E2: 2021 | F2: 2022 | G2: 2023 | H2: 2024
B3: Construcción de edificios | C3: 100 | D3: 106.05 | E3: 127.99 | F3: 158.4 | G3: 157.84 | H3: 162.88
B4: Construcción de obras de ingeniería civil | C4: 100 | D4: 106.98 | E4: 129.11 | F4: 159.77 | G4: 160.88 | H4: 166.09
B5: Actividades especializadas de construcción | C5: 100 | D5: 104.79 | E5: 127.87 | F5: 162.08 | G5: 160.14 | H5: 163.77
B6: Madera aserrada, cepillada y astillada | C6: 100 | D6: 106.16 | E6: 127.33 | F6: 155.4 | G6: 154.55 | H6: 160.29
B7: Tableros y madera prensada | C7: 100 | D7: 104.08 | E7: 125.34 | F7: 154.11 | G7: 142.28 | H7: 144.32
B8: Otros productos químicos básicos | C8: 100 | D8: 111.93 | E8: 140.81 | F8: 177.2 | G8: 159.06 | H8: 168.46
B9: Pinturas y barnices | C9: 100 | D9: 106.95 | E9: 122.72 | F9: 159.5 | G9: 159.23 | H9: 166.3
B10: Productos de plástico | C10: 100 | D10: 103.08 | E10: 110.7 | F10: 133.52 | G10: 148.91 | H10: 166.12
B11: Otros productos de vidrio | C11: 100 | D11: 104.67 | E11: 126.39 | F11: 152.63 | G11: 147.28 | H11: 150.69
B12: Cemento, cal y yeso | C12: 100 | D12: 105.81 | E12: 117.49 | F12: 150.51 | G12: 158.72 | H12: 168.82
B13: Hormigón premezclado | C13: 100 | D13: 103.78 | E13: 117.19 | F13: 140.82 | G13: 144.17 | H13: 140.97
... B23: Muebles | C23: 100 | D23: 108.64 | E23: 125.03 | F23: 132.57 | G23: 130.63 | H23: 133.17

Sheet Construccion 3 (ch)
B2: MERCADO NACIONAL | D2: Departamentos | G2: Casas | J2: Viviendas
D3: Stock | E3: Ventas | F3: Meses | G3: Stock | H3: Ventas | I3: Meses | J3: Stock | K3: Ventas | L3: Meses
B4: 2004 | C4: Ene | D4: 37212 | E4: 1750 | F4: 21.3 | G4: 18771 | H4: 1199 | I4: 15.7 | J4: 55983 | K4: 2949 | L4: 19
C5: Feb | D5: 36793 | E5: 1699 | F5: 21.7 | G5: 17857 | H5: 1214 | I5: 14.7 | J5: 54650 | K5: 2913 | L5: 18.8
C6: Mar | D6: 35743 | E6: 2103 | F6: 17 | G6: 17509 | H6: 1820 | I6: 9.6 | J6: 53252 | K6: 3923 | L6: 13.6
C7: Abr | D7: 35796 | E7: 2272 | F7: 15.8 | G7: 16304 | H7: 1967 | I7: 8.3 | J7: 52099 | K7: 4238 | L7: 12.3
C8: May | D8: 38372 | E8: 2651 | F8: 14.5 | G8: 17056 | H8: 1982 | I8: 8.6 | J8: 55428 | K8: 4633 | L8: 12 | N8: Las cifras fueron revisadas a partir de CASEN 2020, en base a la actualización de la metodología de expansión de las cifras nacionales.
C9: Jun | D9: 36053 | E9: 2522 | F9: 14.3 | G9: 19232 | H9: 1882 | I9: 10.2 | J9: 55285 | K9: 4405 | L9: 12.6
C10: Jul | D10: 36993 | E10: 2965 | F10: 12.5 | G10: 18557 | H10: 2592 | I10: 7.2 | J10: 55550 | K10: 5556 | L10: 10 | N10: Stock: unidades de viviendas (departamentos o casas) disponibles para venta en cada momento del tiempo.
C11: Ago | D11: 35279 | E11: 2912 | F11: 12.1 | G11: 16985 | H11: 2654 | I11: 6.4 | J11: 52265 | K11: 5566 | L11: 9.4 | N11: Ventas: promesas de compraventa firmadas en cada momento del tiempo.
C12: Sep | D12: 37220 | E12: 2679 | F12: 13.9 | G12: 17637 | H12: 2160 | I12: 8.2 | J12: 54857 | K12: 4838 | L12: 11.3 | N12: Meses: medida de la velocidad de ventas que se calcula como el cociente entre el stock disponible en un mes concreto y las unidades vendidas en ese mismo mes. Representa el número de meses necesarios para vender todo el stock disponible asumiendo que el ritmo de ventas se mantendrá estable y no habrá ingreso de nuevas unidades.
C13: Oct | D13: 37797 | E13: 2471 | F13: 15.3 | G13: 17097 | H13: 2245 | I13: 7.6 | J13: 54893 | K13: 4716 | L13: 11.6
C14: Nov | D14: 40766 | E14: 1938 | F14: 21 | G14: 15830 | H14: 1973 | I14: 8 | J14: 56596 | K14: 3911 | L14: 14.5
C15: Dic | D15: 34830 | E15: 1735 | F15: 20.1 | G15: 14846 | H15: 1430 | I15: 10.4 | J15: 49676 | K15: 3164 | L15: 15.7
B16: 2005 | C16: Ene | D16: 35568 | E16: 1870 | F16: 19 | G16: 15008 | H16: 1471 | I16: 10.2 | J16: 50576 | K16: 3341 | L16: 15.1
C17: Feb | D17: 38333 | E17: 1968 | F17: 19.5 | G17: 15590 | H17: 1673 | I17: 9.3 | J17: 53922 | K17: 3641 | L17: 14.8
C18: Mar | D18: 38282 | E18: 1969 | F18: 19.4 | G18: 17175 | H18: 2100 | I18: 8.2 | J18: 55456 | K18: 4069 | L18: 13.6
C19: Abr | D19: 40939 | E19: 2546 | F19: 16.1 | G19: 16545 | H19: 1849 | I19: 8.9 | J19: 57483 | K19: 4395 | L19: 13.1
C20: May | D20: 47786 | E20: 2821 | F20: 16.9 | G20: 16436 | H20: 2612 | I20: 6.3 | J20: 64223 | K20: 5433 | L20: 11.8
C21: Jun | D21: 49856 | E21: 2761 | F21: 18.1 | G21: 15267 | H21: 2307 | I21: 6.6 | J21: 65123 | K21: 5068 | L21: 12.8
C22: Jul | D22: 49296 | E22: 3276 | F22: 15 | G22: 15662 | H22: 2545 | I22: 6.2 | J22: 64958 | K22: 5821 | L22: 11.2
C23: Ago | D23: 47640 | E23: 3471 | F23: 13.7 | G23: 14976 | H23: 2452 | I23: 6.1 | J23: 62615 | K23: 5923 | L23: 10.6
C24: Sep | D24: 46886 | E24: 2953 | F24: 15.9 | G24: 14443 | H24: 2092 | I24: 6.9 | J24: 61329 | K24: 5045 | L24: 12.2
C25: Oct | D25: 45234 | E25: 2572 | F25: 17.6 | G25: 15269 | H25: 2860 | I25: 5.3 | J25: 60503 | K25: 5432 | L25: 11.1
C26: Nov | D26: 43665 | E26: 2834 | F26: 15.4 | G26: 14956 | H26: 2265 | I26: 6.6 | J26: 58621 | K26: 5099 | L26: 11.5
C27: Dic | D27: 43100 | E27: 2066 | F27: 20.9 | G27: 14765 | H27: 1556 | I27: 9.5 | J27: 57865 | K27: 3622 | L27: 16
B28: 2006 | C28: Ene | D28: 43176 | E28: 1980 | F28: 21.8 | G28: 14869 | H28: 1941 | I28: 7.7 | J28: 58045 | K28: 3922 | L28: 14.8
C29: Feb | D29: 42279 | E29: 2196 | F29: 19.3 | G29: 14277 | H29: 2075 | I29: 6.9 | J29: 56556 | K29: 4271 | L29: 13.2
C30: Mar | D30: 43343 | E30: 2578 | F30: 16.8 | G30: 14552 | H30: 1894 | I30: 7.7 | J30: 57895 | K30: 4472 | L30: 12.9
C31: Abr | D31: 41578 | E31: 2313 | F31: 18 | G31: 16750 | H31: 2200 | I31: 7.6 | J31: 58329 | K31: 4513 | L31: 12.9
C32: May | D32: 46248 | E32: 2837 | F32: 16.3 | G32: 16305 | H32: 2317 | I32: 7 | J32: 62553 | K32: 5154 | L32: 12.1
C33: Jun | D33: 47092 | E33: 2782 | F33: 16.9 | G33: 16877 | H33: 2063 | I33: 8.2 | J33: 63968 | K33: 4845 | L33: 13.2
C34: Jul | D34: 52255 | E34: 3307 | F34: 15.8 | G34: 19993 | H34: 2269 | I34: 8.8 | J34: 72248 | K34: 5576 | L34: 13
C35: Ago | D35: 54149 | E35: 3644 | F35: 14.9 | G35: 20928 | H35: 2691 | I35: 7.8 | J35: 75076 | K35: 6335 | L35: 11.9
C36: Sep | D36: 52658 | E36: 2699 | F36: 19.5 | G36: 20057 | H36: 2538 | I36: 7.9 | J36: 72715 | K36: 5237 | L36: 13.9
C37: Oct | D37: 51709 | E37: 3147 | F37: 16.4 | G37: 19458 | H37: 2585 | I37: 7.5 | J37: 71167 | K37: 5732 | L37: 12.4
C38: Nov | D38: 50449 | E38: 2766 | F38: 18.2 | G38: 22644 | H38: 2704 | I38: 8.4 | J38: 73094 | K38: 5470 | L38: 13.4
C39: Dic | D39: 49981 | E39: 2071 | F39: 24.1 | G39: 20843 | H39: 1454 | I39: 14.3 | J39: 70824 | K39: 3525 | L39: 20.1
B40: 2007 | C40: Ene | D40: 49086 | E40: 2447 | F40: 20.1 | G40: 18111 | H40: 1843 | I40: 9.8 | J40: 67197 | K40: 4290 | L40: 15.7
C41: Feb | D41: 48067 | E41: 2587 | F41: 18.6 | G41: 17457 | H41: 1707 | I41: 10.2 | J41: 65524 | K41: 4295 | L41: 15.3
...

Sheet Construccion1 (Mex)
A2: Gasto del producto interno bruto, volumen a precios del año anterior encadenado, series empalmadas, referencia 2018 (miles de millones de pesos encadenados CLP)
A3: Total México | B3: Descripción series | C3: 2002 | D3: 2003 | E3: 2004 | F3: 2005 | G3: 2006 | H3: 2007 | I3: 2008 | J3: 2009 | K3: 2010 | L3: 2011 | M3: 2012 | N3: 2013 | O3: 2014 | P3: 2015 | Q3: 2016 | R3: 2017 | S3: 2018 | T3: 2019 | U3: 2020 | V3: 2021 | W3: 2022 | X3: 2023 | Y3: 2024
B4: Construcción y otras obras | C4: 13963.74 | D4: 15325.32 | E4: 16617.02 | F4: 18525.83 | G4: 19888.48 | H4: 21555.32 | I4: 24178.88 | J4: 22772.09 | K4: 23222.17 | L4: 25594.85 | M4: 28128.62 | N4: 29200.35 | O4: 28398.77 | P4: 29397.74 | Q4: 28739.03 | R4: 27006.44 | S4: 28201.33 | T4: 29664.86 | U4: 26663.74 | V4: 29438.1 | W4: 30850.77 | X4: 30743.33 | Y4: 30637.68
A7: N° de Vivienda
A8: Total México | B8: Descripción series | C8: 2008 | D8: 2009 | E8: 2010 | F8: 2011 | G8: 2012 | H8: 2013 | I8: 2014 | J8: 2015 | K8: 2016 | L8: 2017 | M8: 2018 | N8: 2019 | O8: 2020 | P8: 2021 | Q8: 2022 | R8: 2023 | S8: 2024
B9: Vivienda (número) | C9: 150911 | D9: 140619 | E9: 96036 | F9: 151071 | G9: 117310 | H9: 118796 | I9: 150453 | J9: 179402 | K9: 122967 | L9: 133914 | M9: 150491 | N9: 159182 | O9: 123779 | P9: 146370 | Q9: 117950 | R9: 90589 | S9: 86013
A11: Número de viviendas autorizadas en obras nuevas, total país (CH)
A14: Concepto | B14: 2013 | C14: 2014 | D14: 2015 | E14: 2016 | F14: 2017 | G14: 2018 | H14: 2019 | I14: 2020 | J14: 2021 | K14: 2022 P | L14: 2023 P
A16: PIB de la vivienda | B16: 857.599 | C16: 907.83 | D16: 969.042 | E16: 1,065,073 | F16: 1,156,240 | G16: 1,235,753 | H16: 1,292,515 | I16: 1,180,524 | J16: 1,358,009 | K16: 1,484,766 | L16: 1,596,333
A17: Proporción respecto al total nacional (porcentaje) | B17: 45721 | C17: 45721 | D17: 45721 | E17: 45782 | F17: 45752 | G17: 45752 | H17: 45782 | I17: 45693 | J17: 45752 | K17: 45721 | L17: 45721
A18: PIB de la Vivienda por ámbito económico
A19: Edificación | B19: 536.18 | C19: 570.93 | D19: 618.419 | E19: 694.439 | F19: 780.893 | G19: 847.362 | H19: 887.976 | I19: 755.777 | J19: 905.447 | K19: 1,006,007 | L19: 1,089,415
A20: Adquisición | B20: 62.954 | C20: 64.532 | D20: 68.488 | E20: 76.889 | F20: 70.468 | G20: 72.973 | H20: 75.832 | I20: 83.122 | J20: 94.403 | K20: 100.164 | L20: 112.348
A21: Uso | B21: 253.301 | C21: 265.858 | D21: 276.422 | E21: 287.636 | F21: 297.628 | G21: 308.635 | H21: 324.338 | I21: 337.411 | J21: 353.461 | K21: 373.848 | L21: 390.737
A22: Regulación y fomento | B22: 5.163 | C22: 6.51 | D22: 5.714 | E22: 6.109 | F22: 7.25 | G22: 6.783 | H22: 4.369 | I22: 4.214 | J22: 4.698 | K22: 4.748 | L22: 3.832
A23: Puestos de trabajo (Unidades)1/ | B23: 2,351,170 | C23: 2,329,886 | D23: 2,375,346 | E23: 2,441,326 | F23: 2,467,946 | G23: 2,524,605 | H23: 2,503,717 | I23: 2,340,085 | J23: 2,333,677 | K23: 2,193,530 | L23: 2,185,532
A25: https://www.inegi.org.mx/programas/viviendasat/2018/
A27: Producto Interno Bruto del sector vivienda, Base 2018
A28: Valores corrientes
A29: Millones de pesos y porcentaje
A30: (Mexico)

Sheet Construcción 2. (Mex)
A1: Banco de México
G2: índice de Volumen de la Industria de la Construcción por subsectores: es un indicador real (en cantidades/volumen, no en pesos) que muestra cómo cambia la producción de la construcción y de cada uno de sus subsectores en el tiempo. Se publica por Edificación (236), Obras de ingeniería civil (237) y Trabajos especializados para la construcción (238), y forma parte del Indicador Mensual de la Actividad Industrial (IMAI) del INEGI. Se expresa como un índice con base 2018=100 y se calcula con una metodología tipo Laspeyres (estructura fija del año base). inegi.org.mx Cómo se interpreta Nivel del índice (base 2018=100): si Edificación marca 110, significa que el volumen producido es 10% mayor que en 2018; si marca 90, es 10% menor. inegi.org.mx Variaciones publicadas: se difunden cambios mensuales desestacionalizados (para comparar contra el mes inmediato anterior quitando estacionalidad) y variaciones anuales (respecto al mismo mes del año previo). inegi.org.mx Cobertura y fuentes: el IMAI usa, entre otras, la Encuesta Nacional de Empresas Constructoras (ENEC) para derivar estos índices por subsector; por eso mide volumen real, no valores corrientes. inegi.org.mx Para qué sirve Seguimiento cíclico: permite ver si la construcción acelera o se enfría por tipo de obra (vivienda/edificación, carreteras/infraestructura, instalaciones y acabados). inegi.org.mx Planeación y análisis: es insumo para el PIB industrial, análisis sectoriales y decisiones de política y negocio (por ejemplo, detectar caídas en obra civil versus expansión en edificación).
A3: Producción
A4: Índice de volumen de la industria de la construcción por subsectores
A7: Título | B7: Índice de volumen de la producción industrial, Series originales, Construcción | C7: Índice de volumen de la industria de la construcción por subsectores, Total, Edificación | D7: Índice de volumen de la industria de la construcción por subsectores, Total, Construcción de obras de ingeniería civil u obra pesada
A8: Periodo disponible | B8: Ene 1993 - Ago 2017 | C8: Ene 1993 - Ago 2017 | D8: Ene 1993 - Ago 2017
A9: Periodicidad | B9: Mensual | C9: Mensual | D9: Mensual
A10: Cifra | B10: Indices | C10: Indices | D10: Indices
A11: Unidad | B11: Porcentajes | C11: Porcentajes | D11: Porcentajes
A12: Base | B12: (Base 2008=100) | C12: (Base 2008=100) | D12: (Base 2008=100)
A13: Aviso
A14: Tipo de información | B14: Tasa de crecimiento anual | C14: Tasa de crecimiento anual | D14: Tasa de crecimiento anual
A15: Fecha | B15: SR13813 | C15: SR13850 | D15: SR13851
A16: 36526 | B16: 0.28 | C16: -2.17 | D16: 28.1
A17: 36557 | B17: 4.37 | C17: 2.21 | D17: 32.29
A18: 36586 | B18: 1.4 | C18: -1.43 | D18: 26.9
A19: 36617 | B19: 3.35 | C19: 0.57 | D19: 27.4
A20: 36647 | B20: 5.71 | C20: 2.93 | D20: 27.99
A21: 36678 | B21: 1.04 | C21: -1.75 | D21: 22.41
A22: 36708 | B22: 1.36 | C22: -1.17 | D22: 19.66
A23: 36739 | B23: 3.87 | C23: 0.97 | D23: 22.02
A24: Sep 2000 | B24: -1.2 | C24: -3.58 | D24: 12.6
A25: 36800 | B25: -0.25 | C25: -2.99 | D25: 11.5
A26: 36831 | B26: -3.68 | C26: -6.76 | D26: 5.73
A27: 36861 | B27: -7.08 | C27: -8.83 | D27: -2.02
A28: 36892 | B28: -7.52 | C28: -9.36 | D28: -3.7
A29: 36923 | B29: -11.28 | C29: -12.45 | D29: -10.07
A30: 36951 | B30: -8.64 | C30: -8.66 | D30: -11.58
A31: 36982 | B31: -12.2 | C31: -12.28 | D31: -14.24
A32: 37012 | B32: -11.24 | C32: -10.99 | D32: -14.4
A33: 37043 | B33: -9.8 | C33: -10.19 | D33: -12.26
A34: 37073 | B34: -4.98 | C34: -6.07 | D34: -4.53
A35: 37104 | B35: -5.62 | C35: -6.91 | D35: -3.84
A36: Sep 2001 | B36: -5.57 | C36: -7.59 | D36: 0.25
A37: 37165 | B37: -7.4 | C37: -9.38 | D37: 1.73
A38: 37196 | B38: -5.45 | C38: -7.62 | D38: 6.96
A39: 37226 | B39: -2.98 | C39: -6.07 | D39: 16.82
A40: 37257 | B40: -5.54 | C40: -9.15 | D40: 17.59
A41: 37288 | B41: -3.16 | C41: -6.94 | D41: 26.57
A42: 37316 | B42: -8.59 | C42: -14.28 | D42: 25.01
...

Sheet Salud1(ch)
A2: Ingresos SECTOR PRIVADO (MM$) / % del PIB / N° de Camas Hospitalarias
A3: Año | B3: INGRESOS SECTOR PRIVADO (MM$) | C3: gasto en salud % PIB | D3: camas hospitalarias
A4: 2014 | D4: 38171
A5: 2015 | D5: 38171
A6: 2016 | D6: 37552
A7: 2017 | D7: 38362
A8: 2018 | B8: 8445174 | C8: 9.1 | D8: 38959
A9: 2019 | B9: 8871520 | C9: 9.3 | D9: 38184
A10: 2020 | B10: 8487716 | C10: 9.7 | D10: 38899
A11: 2021 | B11: 10788356 | C11: 9.7 | D11: 38495
A12: 2022 | B12: 12929688 | C12: 10 | D12: 38167
A13: 2023 | B13: 13878518 | C13: 10.2 | D13: 37430
A14: 2024 | B14: 16894843 | C14: 10.5 | D14: 37397

Sheet Salud2(ch)
B1: Chile - Natalidad | E1: Año | F1: Nacimientos registrados | G1: Nota / fuente
A2: Fecha | B2: Tasa Natalidad | C2: Índice de Fecund. | E2: 2011 | F2: 247 358 nacidos vivos. Instituto Nacional de Estadísticas+2La Tercera+2 | G2: Anuario Estadísticas Vitales 2011.
A3: 2023 | B3: 0.00896 | C3: 1.17 | E3: 2015 | F3: 244 670 nacimientos. ADN Radio+2La Nación+2 | G3: Notificado por INE.
A4: 2022 | B4: 0.00967 | C4: 1.26 | E4: 2016 | F4: 231 749 nacimientos. La Nación+1 | G4: Según Anuario 2016.
A5: 2021 | B5: 0.00907 | C5: 1.18 | E5: 2017 | F5: 219 186 nacimientos. Instituto Nacional de Estadísticas | G5: Según Anuario 2017.
A6: 2020 | B6: 0.0101 | C6: 1.31 | E6: 2022 | F6: 189 303 nacimientos. Instituto Nacional de Estadísticas+1 | G6: Estadísticas Vitales 2022.
A7: 2019 | B7: 0.01094 | C7: 1.43 | E7: 2023 (provisionales) | F7: 174 067 nacimientos. Duna+2Instituto Nacional de Estadísticas+2 | G7: Datos provisionales.
A8: 2018 | B8: 0.0117 | C8: 1.54 | E8: 2024 (provisionales) | F8: 154 441 nacimientos. Cooperativa.cl+1 | G8: Boletín Demográfico Anual Provisional.
A9: 2017 | B9: 0.01176 | C9: 1.56
A10: 2016 | B10: 0.01269 | C10: 1.69
A11: 2015 | B11: 0.01315 | C11: 1.74
A12: 2014 | B12: 0.01347 | C12: 1.77
A13: 2013 | B13: 0.01362 | C13: 1.79
A14: 2012 | B14: 0.01378 | C14: 1.8
A15: 2011 | B15: 0.01402 | C15: 1.82

Sheet Salud3(ch)
A1: Chile
A2: 2017 [ Enero - Diciembre ] | E2: CONTROLES SEGÚN PROBLEMA DE SALUD
A3: TIPO DE CONTROL | B3: PROFESIONAL | C3: TOTAL | F3: POR EDAD | AN3: BENEFICIARIOS
F4: 0 - 4 | H4: 45905 | J4: 45944 | L4: 15 - 19 | N4: 20 - 24 | P4: 25 - 29 | R4: 30 - 34 | T4: 35 - 39 | V4: 40 - 44 | X4: 45 - 49 | Z4: 50 - 54 | AB4: 55 - 59 | AD4: 60 - 64 | AF4: 65 - 69 | AH4: 70 - 74 | AJ4: 75 - 79 | AL4: 80 y mas
C5: Ambos Sexos | D5: Hombres | E5: Mujeres | F5: Hombres | G5: Mujeres | H5: Hombres | I5: Mujeres | J5: Hombres | K5: Mujeres | L5: Hombres | M5: Mujeres | N5: Hombres | O5: Mujeres | P5: Hombres | Q5: Mujeres | R5: Hombres | S5: Mujeres | T5: Hombres | U5: Mujeres | V5: Hombres | W5: Mujeres | X5: Hombres | Y5: Mujeres | Z5: Hombres | AA5: Mujeres | AB5: Hombres | AC5: Mujeres | AD5: Hombres | AE5: Mujeres | AF5: Hombres | AG5: Mujeres | AH5: Hombres | AI5: Mujeres | AJ5: Hombres | AK5: Mujeres | AL5: Hombres | AM5: Mujeres
A6: Acumulado Pais
A7: DE SALUD CARDIOVASCULAR | B7: MÉDICO | C7: 2793983 | D7: 1006415 | E7: 1787568 | F7: 0 | G7: 0 | H7: 0 | I7: 0 | J7: 0 | K7: 1 | L7: 2219 | M7: 3486 | N7: 2855 | O7: 6490 | P7: 5543 | Q7: 12306 | R7: 9356 | S7: 20623 | T7: 17271 | U7: 36776 | V7: 31427 | W7: 66695 | X7: 54203 | Y7: 118671 | Z7: 93470 | AA7: 194462 | AB7: 120306 | AC7: 228535 | AD7: 138335 | AE7: 247051 | AF7: 149354 | AG7: 243055 | AH7: 148034 | AI7: 226020 | AJ7: 114488 | AK7: 176401 | AL7: 119526 | AM7: 206936 | AN7: 2757706
B8: ENFERMERA /O | C8: 1305552 | D8: 469444 | E8: 836108 | F8: 0 | G8: 0 | H8: 0 | I8: 0 | J8: 0 | K8: 0 | L8: 514 | M8: 726 | N8: 1048 | O8: 1866 | P8: 2050 | Q8: 3771 | R8: 3434 | S8: 6999 | T8: 6654 | U8: 13974 | V8: 12542 | W8: 26894 | X8: 22692 | Y8: 50016 | Z8: 39772 | AA8: 84126 | AB8: 52680 | AC8: 102913 | AD8: 61825 | AE8: 113664 | AF8: 71197 | AG8: 120082 | AH8: 74931 | AI8: 115611 | AJ8: 58263 | AK8: 91033 | AL8: 61854 | AM8: 104496 | AN8: 1289563
B9: NUTRICIONISTA | C9: 1082967 | D9: 366667 | E9: 716308 | F9: 0 | G9: 0 | H9: 0 | I9: 0 | J9: 0 | K9: 0 | L9: 1006 | M9: 1999 | N9: 1467 | O9: 3806 | P9: 2550 | Q9: 6473 | R9: 4079 | S9: 9942 | T9: 7357 | U9: 17007 | V9: 12623 | W9: 29629 | X9: 21490 | Y9: 51986 | Z9: 34801 | AA9: 82324 | AB9: 44202 | AC9: 94568 | AD9: 49314 | AE9: 98116 | AF9: 53606 | AG9: 96451 | AH9: 54157 | AI9: 88751 | AJ9: 40435 | AK9: 65781 | AL9: 39571 | AM9: 69479 | AN9: 1066882
B10: TÉCNICO PARAMÉDICO | C10: 112456 | D10: 42378 | E10: 70078 | F10: 0 | G10: 0 | H10: 0 | I10: 0 | J10: 0 | K10: 0 | L10: 197 | M10: 272 | N10: 228 | O10: 352 | P10: 339 | Q10: 576 | R10: 522 | S10: 1072 | T10: 993 | U10: 1753 | V10: 1519 | W10: 3207 | X10: 2472 | Y10: 5129 | Z10: 3940 | AA10: 7646 | AB10: 4807 | AC10: 9054 | AD10: 5343 | AE10: 9639 | AF10: 6142 | AG10: 9662 | AH10: 6249 | AI10: 8046 | AJ10: 4660 | AK10: 6036 | AL10: 4962 | AM10: 7639 | AN10: 109255
A11: DE TUBERCULOSIS | B11: MÉDICO | C11: 8984 | D11: 5120 | E11: 3864 | F11: 114 | G11: 95 | H11: 131 | I11: 135 | J11: 121 | K11: 131 | L11: 197 | M11: 167 | N11: 342 | O11: 267 | P11: 483 | Q11: 333 | R11: 480 | S11: 297 | T11: 346 | U11: 253 | V11: 373 | W11: 227 | X11: 387 | Y11: 223 | Z11: 469 | AA11: 221 | AB11: 434 | AC11: 300 | AD11: 325 | AE11: 275 | AF11: 246 | AG11: 284 | AH11: 212 | AI11: 273 | AJ11: 246 | AK11: 150 | AL11: 214 | AM11: 233 | AN11: 8626
B12: ENFERMERA /O | C12: 6742 | D12: 3793 | E12: 2949 | F12: 136 | G12: 109 | H12: 93 | I12: 97 | J12: 159 | K12: 129 | L12: 147 | M12: 125 | N12: 285 | O12: 302 | P12: 342 | Q12: 244 | R12: 260 | S12: 246 | T12: 230 | U12: 141 | V12: 236 | W12: 184 | X12: 290 | Y12: 175 | Z12: 272 | AA12: 143 | AB12: 282 | AC12: 176 | AD12: 298 | AE12: 191 | AF12: 209 | AG12: 175 | AH12: 197 | AI12: 220 | AJ12: 144 | AK12: 134 | AL12: 213 | AM12: 158 | AN12: 6419
A13: SEGUIMIENTO AUTOVALENTE CON RIESGO | B13: MÉDICO | C13: 1731 | D13: 641 | E13: 1090 | F13: 0 | G13: 0 | H13: 0 | I13: 0 | J13: 0 | K13: 0 | L13: 0 | M13: 0 | N13: 0 | O13: 0 | P13: 0 | Q13: 0 | R13: 0 | S13: 0 | T13: 0 | U13: 0 | V13: 0 | W13: 0 | X13: 0 | Y13: 0 | Z13: 0 | AA13: 0 | AB13: 0 | AC13: 0 | AD13: 0 | AE13: 0 | AF13: 153 | AG13: 288 | AH13: 197 | AI13: 270 | AJ13: 148 | AK13: 259 | AL13: 143 | AM13: 273 | AN13: 1678
B14: ENFERMERA /O | C14: 23666 | D14: 8489 | E14: 15177 | F14: 0 | G14: 0 | H14: 0 | I14: 0 | J14: 0 | K14: 0 | L14: 0 | M14: 0 | N14: 0 | O14: 0 | P14: 0 | Q14: 0 | R14: 0 | S14: 0 | T14: 0 | U14: 0 | V14: 0 | W14: 0 | X14: 0 | Y14: 0 | Z14: 0 | AA14: 0 | AB14: 0 | AC14: 0 | AD14: 0 | AE14: 0 | AF14: 2154 | AG14: 4151 | AH14: 2599 | AI14: 4591 | AJ14: 2091 | AK14: 3443 | AL14: 1642 | AM14: 2981 | AN14: 23382
A15: SEGUIMIENTO RIESGO DEPENDENCIA | B15: MÉDICO | C15: 778 | D15: 279 | E15: 499 | F15: 0 | G15: 0 | H15: 0 | I15: 0 | J15: 0 | K15: 0 | L15: 0 | M15: 0 | N15: 0 | O15: 0 | P15: 0 | Q15: 0 | R15: 0 | S15: 0 | T15: 0 | U15: 0 | V15: 0 | W15: 0 | X15: 0 | Y15: 0 | Z15: 0 | AA15: 0 | AB15: 0 | AC15: 0 | AD15: 0 | AE15: 0 | AF15: 48 | AG15: 80 | AH15: 52 | AI15: 93 | AJ15: 58 | AK15: 111 | AL15: 121 | AM15: 215 | AN15: 774
B16: ENFERMERA /O | C16: 14077 | D16: 4680 | E16: 9397 | F16: 0 | G16: 0 | H16: 0 | I16: 0 | J16: 0 | K16: 0 | L16: 0 | M16: 0 | N16: 0 | O16: 0 | P16: 0 | Q16: 0 | R16: 0 | S16: 0 | T16: 0 | U16: 0 | V16: 0 | W16: 0 | X16: 0 | Y16: 0 | Z16: 0 | AA16: 0 | AB16: 0 | AC16: 0 | AD16: 0 | AE16: 0 | AF16: 555 | AG16: 1128 | AH16: 971 | AI16: 1736 | AJ16: 1111 | AK16: 2308 | AL16: 2038 | AM16: 4217 | AN16: 13840
A17: DE INFECCIÓN TRANSMISIÓN SEXUAL | B17: MÉDICO | C17: 4522 | D17: 1501 | E17: 3021 | F17: 34 | G17: 37 | H17: 40 | I17: 30 | J17: 24 | K17: 23 | L17: 72 | M17: 156 | N17: 178 | O17: 219 | P17: 94 | Q17: 182 | R17: 71 | S17: 155 | T17: 49 | U17: 127 | V17: 56 | W17: 150 | X17: 76 | Y17: 208 | Z17: 113 | AA17: 226 | AB17: 102 | AC17: 299 | AD17: 139 | AE17: 275 | AF17: 120 | AG17: 293 | AH17: 114 | AI17: 284 | AJ17: 114 | AK17: 180 | AL17: 105 | AM17: 177 | AN17: 4219
B18: ENFERMERA /O | C18: 616 | D18: 282 | E18: 334 | F18: 16 | G18: 8 | H18: 10 | I18: 7 | J18: 0 | K18: 1 | L18: 7 | M18: 13 | N18: 21 | O18: 16 | P18: 15 | Q18: 17 | R18: 9 | S18: 17 | T18: 11 | U18: 12 | V18: 5 | W18: 8 | X18: 12 | Y18: 17 | Z18: 18 | AA18: 25 | AB18: 23 | AC18: 31 | AD18: 17 | AE18: 26 | AF18: 28 | AG18: 29 | AH18: 27 | AI18: 42 | AJ18: 31 | AK18: 25 | AL18: 32 | AM18: 40 | AN18: 542
B19: MATRONA /ÓN | C19: 7057 | D19: 1905 | E19: 5152 | F19: 10 | G19: 8 | H19: 3 | I19: 13 | J19: 8 | K19: 36 | L19: 254 | M19: 709 | N19: 429 | O19: 922 | P19: 303 | Q19: 736 | R19: 152 | S19: 595 | T19: 130 | U19: 544 | V19: 109 | W19: 445 | X19: 95 | Y19: 318 | Z19: 115 | AA19: 226 | AB19: 98 | AC19: 180 | AD19: 50 | AE19: 129 | AF19: 55 | AG19: 86 | AH19: 32 | AI19: 85 | AJ19: 20 | AK19: 55 | AL19: 42 | AM19: 65 | AN19: 6731
A20: OTROS PROBLEMAS DE SALUD | B20: MÉDICO | C20: 640824 | D20: 176686 | E20: 464139 | F20: 6878 | G20: 5802 | H20: 5501 | I20: 4649 | J20: 5599 | K20: 4826 | L20: 4518 | M20: 7499 | N20: 3506 | O20: 9073 | P20: 3827 | Q20: 12640 | R20: 4105 | S20: 14314 | T20: 4773 | U20: 17634 | V20: 6079 | W20: 22940 | X20: 8806 | Y20: 31977 | Z20: 12617 | AA20: 44548 | AB20: 15921 | AC20: 52706 | AD20: 17778 | AE20: 54716 | AF20: 19533 | AG20: 53322 | AH20: 20193 | AI20: 48061 | AJ20: 17306 | AK20: 36449 | AL20: 19748 | AM20: 42985 | AN20: 627792
B21: ENFERMERA /O | C21: 85890 | D21: 31033 | E21: 54858 | F21: 1407 | G21: 1313 | H21: 747 | I21: 660 | J21: 508 | K21: 460 | L21: 454 | M21: 615 | N21: 379 | O21: 671 | P21: 431 | Q21: 955 | R21: 512 | S21: 1144 | T21: 551 | U21: 1660 | V21: 943 | W21: 2172 | X21: 1406 | Y21: 3407 | Z21: 2292 | AA21: 4759 | AB21: 2742 | AC21: 5459 | AD21: 3041 | AE21: 6294 | AF21: 3916 | AG21: 6977 | AH21: 4420 | AI21: 6789 | AJ21: 3598 | AK21: 5147 | AL21: 3689 | AM21: 6375 | AN21: 84606
B22: MATRONA /ÓN | C22: 14220 | D22: 2131 | E22: 12089 | F22: 693 | G22: 729 | H22: 61 | I22: 129 | J22: 78 | K22: 179 | L22: 40 | M22: 659 | N22: 65 | O22: 784 | P22: 76 | Q22: 894 | R22: 47 | S22: 790 | T22: 59 | U22: 700 | V22: 35 | W22: 916 | X22: 107 | Y22: 900 | Z22: 201 | AA22: 1131 | AB22: 208 | AC22: 1156 | AD22: 49 | AE22: 1047 | AF22: 179 | AG22: 823 | AH22: 85 | AI22: 695 | AJ22: 105 | AK22: 307 | AL22: 42 | AM22: 250 | AN22: 14043
B23: NUTRICIONISTA | C23: 152533 | D23: 54902 | E23: 97632 | F23: 28910 | G23: 28301 | H23: 6933 | I23: 7340 | J23: 2989 | K23: 3654 | L23: 1373 | M23: 5087 | N23: 875 | O23: 5337 | P23: 999 | Q23: 6201 | R23: 889 | S23: 5227 | T23: 865 | U23: 4479 | V23: 878 | W23: 4018 | X23: 1009 | Y23: 4401 | Z23: 1232 | AA23: 4873 | AB23: 1439 | AC23: 4474 | AD23: 1276 | AE23: 3782 | AF23: 1396 | AG23: 3439 | AH23: 1479 | AI23: 2862 | AJ23: 1100 | AK23: 1920 | AL23: 1261 | AM23: 2245 | AN23: 146638
B24: TÉCNICO PARAMÉDICO | C24: 60240 | D24: 25645 | E24: 34598 | F24: 1935 | G24: 1901 | H24: 1026 | I24: 1240 | J24: 1087 | K24: 1099 | L24: 798 | M24: 1126 | N24: 794 | O24: 1110 | P24: 1024 | Q24: 1586 | R24: 1012 | S24: 1771 | T24: 1129 | U24: 1737 | V24: 1331 | W24: 2144 | X24: 1596 | Y24: 2554 | Z24: 1915 | AA24: 2815 | AB24: 1881 | AC24: 2866 | AD24: 1876 | AE24: 2891 | AF24: 2124 | AG24: 2593 | AH24: 2113 | AI24: 2452 | AJ24: 1881 | AK24: 2148 | AL24: 2123 | AM24: 2565 | AN24: 58945
A25: NIÑOS CON NECESIDADES ESPECIALES | B25: MÉDICO | C25: 790 | D25: 428 | E25: 362 | F25: 320 | G25: 248 | H25: 54 | I25: 59 | J25: 28 | K25: 38 | L25: 21 | M25: 11 | N25: 5 | O25: 6 | P25: 0 | Q25: 0 | R25: 0 | S25: 0 | T25: 0 | U25: 18 | V25: 0 | W25: 0 | X25: 0 | Y25: 0 | Z25: 0 | AA25: 0 | AB25: 0 | AC25: 0 | AD25: 0 | AE25: 0 | AF25: 0 | AG25: 0 | AH25: 0 | AI25: 0 | AJ25: 0 | AK25: 0 | AL25: 0 | AM25: 0 | AN25: 757
B26: ENFERMERA /O | C26: 1860 | D26: 1001 | E26: 859 | F26: 802 | G26: 699 | H26: 134 | I26: 106 | J26: 36 | K26: 30 | L26: 22 | M26: 13 | N26: 7 | O26: 11 | P26: 0 | Q26: 0 | R26: 0 | S26: 0 | T26: 0 | U26: 18 | V26: 0 | W26: 0 | X26: 0 | Y26: 0 | Z26: 0 | AA26: 0 | AB26: 0 | AC26: 0 | AD26: 0 | AE26: 0 | AF26: 0 | AG26: 0 | AH26: 0 | AI26: 0 | AJ26: 0 | AK26: 0 | AL26: 0 | AM26: 0 | AN26: 1711
B27: MATRONA /ÓN | C27: 128 | D27: 54 | E27: 74 | F27: 38 | G27: 32 | H27: 3 | I27: 4 | J27: 8 | K27: 13 | L27: 5 | M27: 11 | N27: 0 | O27: 14 | P27: 0 | Q27: 0 | R27: 0 | S27: 0 | T27: 0 | U27: 18 | V27: 0 | W27: 0 | X27: 0 | Y27: 0 | Z27: 1 | AA27: 0 | AB27: 0 | AC27: 0 | AD27: 0 | AE27: 0 | AF27: 0 | AG27: 0 | AH27: 0 | AI27: 0 | AJ27: 0 | AK27: 0 | AL27: 0 | AM27: 0 | AN27: 121
B28: NUTRICIONISTA | C28: 1145 | D28: 562 | E28: 583 | F28: 432 | G28: 474 | H28: 81 | I28: 51 | J28: 25 | K28: 24 | L28: 22 | M28: 23 | N28: 2 | O28: 11 | P28: 0 | Q28: 0 | R28: 0 | S28: 0 | T28: 0 | U28: 18 | V28: 0 | W28: 0 | X28: 0 | Y28: 0 | Z28: 0 | AA28: 0 | AB28: 0 | AC28: 0 | AD28: 0 | AE28: 0 | AF28: 0 | AG28: 0 | AH28: 0 | AI28: 0 | AJ28: 0 | AK28: 0 | AL28: 0 | AM28: 0 | AN28: 1057
B29: TÉCNICO PARAMÉDICO | C29: 114 | D29: 64 | E29: 50 | F29: 21 | G29: 13 | H29: 15 | I29: 5 | J29: 16 | K29: 7 | L29: 6 | M29: 3 | N29: 6 | O29: 4 | P29: 0 | Q29: 0 | R29: 0 | S29: 0 | T29: 0 | U29: 18 | V29: 0 | W29: 0 | X29: 0 | Y29: 0 | Z29: 0 | AA29: 0 | AB29: 0 | AC29: 0 | AD29: 0 | AE29: 0 | AF29: 0 | AG29: 0 | AH29: 0 | AI29: 0 | AJ29: 0 | AK29: 0 | AL29: 0 | AM29: 0 | AN29: 91
A30: Servicio: Arica
A31: DE SALUD CARDIOVASCULAR | B31: MÉDICO | C31: 17290 | D31: 6361 | E31: 10929 | F31: 0 | G31: 0 | H31: 0 | I31: 0 | J31: 0 | K31: 0 | L31: 5 | M31: 11 | N31: 21 | O31: 24 | P31: 37 | Q31: 44 | R31: 39 | S31: 76 | T31: 85 | U31: 161 | V31: 122 | W31: 308 | X31: 261 | Y31: 507 | Z31: 451 | AA31: 1060 | AB31: 641 | AC31: 1249 | AD31: 841 | AE31: 1448 | AF31: 909 | AG31: 1653 | AH31: 1222 | AI31: 1727 | AJ31: 917 | AK31: 1255 | AL31: 810 | AM31: 1406 | AN31: 17288
B32: ENFERMERA /O | C32: 17428 | D32: 6887 | E32: 10541 | F32: 0 | G32: 0 | H32: 0 | I32: 0 | J32: 0 | K32: 0 | L32: 6 | M32: 4 | N32: 9 | O32: 30 | P32: 40 | Q32: 40 | R32: 46 | S32: 81 | T32: 84 | U32: 168 | V32: 182 | W32: 320 | X32: 319 | Y32: 527 | Z32: 530 | AA32: 1002 | AB32: 753 | AC32: 1247 | AD32: 925 | AE32: 1405 | AF32: 976 | AG32: 1559 | AH32: 1268 | AI32: 1499 | AJ32: 839 | AK32: 1172 | AL32: 910 | AM32: 1487 | AN32: 17425
B33: NUTRICIONISTA | C33: 9958 | D33: 3578 | E33: 6380 | F33: 0 | G33: 0 | H33: 0 | I33: 0 | J33: 0 | K33: 0 | L33: 4 | M33: 7 | N33: 8 | O33: 13 | P33: 19 | Q33: 26 | R33: 34 | S33: 48 | T33: 56 | U33: 101 | V33: 88 | W33: 211 | X33: 183 | Y33: 297 | Z33: 252 | AA33: 597 | AB33: 351 | AC33: 756 | AD33: 455 | AE33: 868 | AF33: 526 | AG33: 966 | AH33: 658 | AI33: 964 | AJ33: 474 | AK33: 698 | AL33: 470 | AM33: 828 | AN33: 9957
B34: TÉCNICO PARAMÉDICO | C34: 333 | D34: 149 | E34: 184 | F34: 0 | G34: 0 | H34: 0 | I34: 0 | J34: 0 | K34: 0 | L34: 0 | M34: 0 | N34: 0 | O34: 0 | P34: 4 | Q34: 3 | R34: 1 | S34: 3 | T34: 1 | U34: 5 | V34: 0 | W34: 6 | X34: 9 | Y34: 5 | Z34: 36 | AA34: 25 | AB34: 24 | AC34: 7 | AD34: 9 | AE34: 10 | AF34: 12 | AG34: 34 | AH34: 27 | AI34: 37 | AJ34: 14 | AK34: 18 | AL34: 12 | AM34: 31 | AN34: 327
A35: DE TUBERCULOSIS | B35: MÉDICO | C35: 289 | D35: 160 | E35: 129 | F35: 0 | G35: 0 | H35: 0 | I35: 0 | J35: 1 | K35: 0 | L35: 0 | M35: 4 | N35: 7 | O35: 13 | P35: 20 | Q35: 8 | R35: 11 | S35: 5 | T35: 6 | U35: 3 | V35: 19 | W35: 3 | X35: 11 | Y35: 8 | Z35: 13 | AA35: 15 | AB35: 16 | AC35: 7 | AD35: 21 | AE35: 2 | AF35: 1 | AG35: 25 | AH35: 9 | AI35: 26 | AJ35: 15 | AK35: 5 | AL35: 10 | AM35: 5 | AN35: 289
B36: ENFERMERA /O | C36: 151 | D36: 96 | E36: 55 | F36: 0 | G36: 0 | H36: 1 | I36: 1 | J36: 3 | K36: 0 | L36: 3 | M36: 4 | N36: 13 | O36: 11 | P36: 8 | Q36: 2 | R36: 9 | S36: 6 | T36: 0 | U36: 3 | V36: 13 | W36: 3 | X36: 4 | Y36: 2 | Z36: 4 | AA36: 4 | AB36: 19 | AC36: 3 | AD36: 3 | AE36: 0 | AF36: 0 | AG36: 2 | AH36: 9 | AI36: 12 | AJ36: 6 | AK36: 0 | AL36: 1 | AM36: 2 | AN36: 151
A37: SEGUIMIENTO AUTOVALENTE CON RIESGO | B37: MÉDICO | C37: 120 | D37: 46 | E37: 74 | F37: 0 | G37: 0 | H37: 0 | I37: 0 | J37: 0 | K37: 0 | L37: 0 | M37: 0 | N37: 0 | O37: 0 | P37: 0 | Q37: 0 | R37: 0 | S37: 0 | T37: 0 | U37: 0 | V37: 0 | W37: 0 | X37: 0 | Y37: 0 | Z37: 0 | AA37: 0 | AB37: 0 | AC37: 0 | AD37: 0 | AE37: 0 | AF37: 6 | AG37: 9 | AH37: 13 | AI37: 16 | AJ37: 12 | AK37: 24 | AL37: 15 | AM37: 25 | AN37: 120
B38: ENFERMERA /O | C38: 318 | D38: 99 | E38: 219 | F38: 0 | G38: 0 | H38: 0 | I38: 0 | J38: 0 | K38: 0 | L38: 0 | M38: 0 | N38: 0 | O38: 0 | P38: 0 | Q38: 0 | R38: 0 | S38: 0 | T38: 0 | U38: 0 | V38: 0 | W38: 0 | X38: 0 | Y38: 0 | Z38: 0 | AA38: 0 | AB38: 0 | AC38: 0 | AD38: 0 | AE38: 0 | AF38: 10 | AG38: 68 | AH38: 44 | AI38: 59 | AJ38: 30 | AK38: 69 | AL38: 15 | AM38: 23 | AN38: 317
A39: SEGUIMIENTO RIESGO DEPENDENCIA | B39: MÉDICO | C39: 108 | D39: 41 | E39: 67 | F39: 0 | G39: 0 | H39: 0 | I39: 0 | J39: 0 | K39: 0 | L39: 0 | M39: 0 | N39: 0 | O39: 0 | P39: 0 | Q39: 0 | R39: 0 | S39: 0 | T39: 0 | U39: 0 | V39: 0 | W39: 0 | X39: 0 | Y39: 0 | Z39: 0 | AA39: 0 | AB39: 0 | AC39: 0 | AD39: 0 | AE39: 0 | AF39: 5 | AG39: 10 | AH39: 9 | AI39: 14 | AJ39: 7 | AK39: 15 | AL39: 20 | AM39: 28 | AN39: 108
B40: ENFERMERA /O | C40: 229 | D40: 70 | E40: 159 | F40: 0 | G40: 0 | H40: 0 | I40: 0 | J40: 0 | K40: 0 | L40: 0 | M40: 0 | N40: 0 | O40: 0 | P40: 0 | Q40: 0 | R40: 0 | S40: 0 | T40: 0 | U40: 0 | V40: 0 | W40: 0 | X40: 0 | Y40: 0 | Z40: 0 | AA40: 0 | AB40: 0 | AC40: 0 | AD40: 0 | AE40: 0 | AF40: 8 | AG40: 16 | AH40: 15 | AI40: 40 | AJ40: 18 | AK40: 42 | AL40: 29 | AM40: 61 | AN40: 225
...

Sheet Controles según problema de sal
A1: 2018 [ Enero - Diciembre ] | E1: CONTROLES SEGÚN PROBLEMA DE SALUD
A2: TIPO DE CONTROL | B2: PROFESIONAL | C2: TOTAL | F2: POR EDAD | AN2: BENEFICIARIOS
F3: 0 - 4 | H3: 45905 | J3: 45944 | L3: 15 - 19 | N3: 20 - 24 | P3: 25 - 29 | R3: 30 - 34 | T3: 35 - 39 | V3: 40 - 44 | X3: 45 - 49 | Z3: 50 - 54 | AB3: 55 - 59 | AD3: 60 - 64 | AF3: 65 - 69 | AH3: 70 - 74 | AJ3: 75 - 79 | AL3: 80 y mas
C4: Ambos Sexos | D4: Hombres | E4: Mujeres | F4: Hombres | G4: Mujeres | H4: Hombres | I4: Mujeres | J4: Hombres | K4: Mujeres | L4: Hombres | M4: Mujeres | N4: Hombres | O4: Mujeres | P4: Hombres | Q4: Mujeres | R4: Hombres | S4: Mujeres | T4: Hombres | U4: Mujeres | V4: Hombres | W4: Mujeres | X4: Hombres | Y4: Mujeres | Z4: Hombres | AA4: Mujeres | AB4: Hombres | AC4: Mujeres | AD4: Hombres | AE4: Mujeres | AF4: Hombres | AG4: Mujeres | AH4: Hombres | AI4: Mujeres | AJ4: Hombres | AK4: Mujeres | AL4: Hombres | AM4: Mujeres
A5: Acumulado Pais
A6: DE SALUD CARDIOVASCULAR | B6: MÉDICO | C6: 2900511 | D6: 1050710 | E6: 1849815 | F6: 0 | G6: 0 | H6: 0 | I6: 0 | J6: 0 | K6: 0 | L6: 1968 | M6: 3082 | N6: 2754 | O6: 6079 | P6: 5586 | Q6: 12319 | R6: 9340 | S6: 20733 | T6: 17184 | U6: 36752 | V6: 30585 | W6: 66181 | X6: 53624 | Y6: 116524 | Z6: 92911 | AA6: 194785 | AB6: 126974 | AC6: 239999 | AD6: 146278 | AE6: 256955 | AF6: 157480 | AG6: 253533 | AH6: 157647 | AI6: 238296 | AJ6: 122664 | AK6: 187835 | AL6: 126033 | AM6: 217273 | AN6: 2870098
B7: ENFERMERA /O | C7: 1322084 | D7: 478473 | E7: 843611 | F7: 0 | G7: 0 | H7: 0 | I7: 0 | J7: 0 | K7: 0 | L7: 490 | M7: 701 | N7: 980 | O7: 1592 | P7: 1926 | Q7: 3758 | R7: 3429 | S7: 6787 | T7: 6297 | U7: 13456 | V7: 11978 | W7: 26034 | X7: 21445 | Y7: 48279 | Z7: 38590 | AA7: 82504 | AB7: 53340 | AC7: 103725 | AD7: 63352 | AE7: 115049 | AF7: 74461 | AG7: 122516 | AH7: 77172 | AI7: 117861 | AJ7: 61285 | AK7: 93115 | AL7: 63728 | AM7: 108234 | AN7: 1309557
B8: NUTRICIONISTA | C8: 1111789 | D8: 379451 | E8: 732338 | F8: 0 | G8: 0 | H8: 0 | I8: 0 | J8: 0 | K8: 0 | L8: 834 | M8: 1682 | N8: 1288 | O8: 3385 | P8: 2388 | Q8: 6139 | R8: 3886 | S8: 9441 | T8: 6988 | U8: 16578 | V8: 11953 | W8: 28331 | X8: 20562 | Y8: 49780 | Z8: 34300 | AA8: 82024 | AB8: 45888 | AC8: 97679 | AD8: 52135 | AE8: 102073 | AF8: 56889 | AG8: 99888 | AH8: 57413 | AI8: 92312 | AJ8: 43529 | AK8: 69745 | AL8: 41396 | AM8: 73282 | AN8: 1099332
B9: TÉCNICO PARAMÉDICO | C9: 92806 | D9: 34235 | E9: 58571 | F9: 0 | G9: 0 | H9: 0 | I9: 0 | J9: 0 | K9: 0 | L9: 134 | M9: 167 | N9: 121 | O9: 263 | P9: 278 | Q9: 484 | R9: 380 | S9: 865 | T9: 670 | U9: 1366 | V9: 1055 | W9: 2373 | X9: 1912 | Y9: 4004 | Z9: 3105 | AA9: 6364 | AB9: 3912 | AC9: 7619 | AD9: 4303 | AE9: 8142 | AF9: 4990 | AG9: 7904 | AH9: 5121 | AI9: 7180 | AJ9: 3889 | AK9: 5303 | AL9: 4365 | AM9: 6537 | AN9: 92097
A10: DE TUBERCULOSIS | B10: MÉDICO | C10: 11070 | D10: 6218 | E10: 4852 | F10: 137 | G10: 139 | H10: 155 | I10: 140 | J10: 130 | K10: 106 | L10: 215 | M10: 211 | N10: 453 | O10: 364 | P10: 638 | Q10: 436 | R10: 498 | S10: 417 | T10: 553 | U10: 302 | V10: 460 | W10: 315 | X10: 414 | Y10: 310 | Z10: 494 | AA10: 350 | AB10: 453 | AC10: 417 | AD10: 540 | AE10: 365 | AF10: 329 | AG10: 321 | AH10: 266 | AI10: 251 | AJ10: 249 | AK10: 178 | AL10: 234 | AM10: 230 | AN10: 10594
B11: ENFERMERA /O | C11: 9612 | D11: 5416 | E11: 4196 | F11: 218 | G11: 220 | H11: 152 | I11: 148 | J11: 142 | K11: 105 | L11: 359 | M11: 178 | N11: 425 | O11: 406 | P11: 631 | Q11: 352 | R11: 394 | S11: 583 | T11: 705 | U11: 295 | V11: 329 | W11: 222 | X11: 250 | Y11: 247 | Z11: 366 | AA11: 299 | AB11: 362 | AC11: 219 | AD11: 469 | AE11: 212 | AF11: 183 | AG11: 261 | AH11: 143 | AI11: 191 | AJ11: 125 | AK11: 114 | AL11: 163 | AM11: 144 | AN11: 9200
A12: SEGUIMIENTO AUTOVALENTE CON RIESGO | B12: MÉDICO | C12: 2183 | D12: 887 | E12: 1296 | F12: 0 | G12: 0 | H12: 0 | I12: 0 | J12: 0 | K12: 0 | L12: 0 | M12: 0 | N12: 0 | O12: 0 | P12: 0 | Q12: 0 | R12: 0 | S12: 0 | T12: 0 | U12: 0 | V12: 0 | W12: 0 | X12: 0 | Y12: 0 | Z12: 0 | AA12: 0 | AB12: 0 | AC12: 0 | AD12: 0 | AE12: 0 | AF12: 212 | AG12: 323 | AH12: 216 | AI12: 282 | AJ12: 229 | AK12: 265 | AL12: 230 | AM12: 426 | AN12: 2179
B13: ENFERMERA /O | C13: 23215 | D13: 8542 | E13: 14673 | F13: 0 | G13: 0 | H13: 0 | I13: 0 | J13: 0 | K13: 0 | L13: 0 | M13: 0 | N13: 0 | O13: 0 | P13: 0 | Q13: 0 | R13: 0 | S13: 0 | T13: 0 | U13: 0 | V13: 0 | W13: 0 | X13: 0 | Y13: 0 | Z13: 0 | AA13: 0 | AB13: 0 | AC13: 0 | AD13: 0 | AE13: 0 | AF13: 2202 | AG13: 4086 | AH13: 2688 | AI13: 4359 | AJ13: 2082 | AK13: 3290 | AL13: 1570 | AM13: 2938 | AN13: 22890
A14: SEGUIMIENTO RIESGO DEPENDENCIA | B14: MÉDICO | C14: 719 | D14: 264 | E14: 455 | F14: 0 | G14: 0 | H14: 0 | I14: 0 | J14: 0 | K14: 0 | L14: 0 | M14: 0 | N14: 0 | O14: 0 | P14: 0 | Q14: 0 | R14: 0 | S14: 0 | T14: 0 | U14: 0 | V14: 0 | W14: 0 | X14: 0 | Y14: 0 | Z14: 0 | AA14: 0 | AB14: 0 | AC14: 0 | AD14: 0 | AE14: 0 | AF14: 38 | AG14: 62 | AH14: 42 | AI14: 84 | AJ14: 64 | AK14: 110 | AL14: 120 | AM14: 199 | AN14: 712
B15: ENFERMERA /O | C15: 14359 | D15: 4990 | E15: 9369 | F15: 0 | G15: 0 | H15: 0 | I15: 0 | J15: 0 | K15: 0 | L15: 0 | M15: 0 | N15: 0 | O15: 0 | P15: 0 | Q15: 0 | R15: 0 | S15: 0 | T15: 0 | U15: 0 | V15: 0 | W15: 0 | X15: 0 | Y15: 0 | Z15: 0 | AA15: 0 | AB15: 0 | AC15: 0 | AD15: 0 | AE15: 0 | AF15: 635 | AG15: 1204 | AH15: 948 | AI15: 1750 | AJ15: 1202 | AK15: 2020 | AL15: 2205 | AM15: 4395 | AN15: 14194
A16: DE INFECCIÓN TRANSMISIÓN SEXUAL | B16: MÉDICO | C16: 2966 | D16: 1031 | E16: 1935 | F16: 11 | G16: 16 | H16: 20 | I16: 8 | J16: 30 | K16: 14 | L16: 54 | M16: 85 | N16: 125 | O16: 136 | P16: 82 | Q16: 143 | R16: 81 | S16: 96 | T16: 42 | U16: 76 | V16: 47 | W16: 99 | X16: 48 | Y16: 102 | Z16: 63 | AA16: 141 | AB16: 55 | AC16: 188 | AD16: 94 | AE16: 221 | AF16: 61 | AG16: 214 | AH16: 67 | AI16: 162 | AJ16: 78 | AK16: 113 | AL16: 73 | AM16: 121 | AN16: 2940
B17: ENFERMERA /O | C17: 516 | D17: 198 | E17: 318 | F17: 6 | G17: 6 | H17: 3 | I17: 12 | J17: 4 | K17: 5 | L17: 12 | M17: 8 | N17: 25 | O17: 19 | P17: 14 | Q17: 22 | R17: 18 | S17: 26 | T17: 18 | U17: 32 | V17: 21 | W17: 26 | X17: 7 | Y17: 31 | Z17: 12 | AA17: 24 | AB17: 7 | AC17: 26 | AD17: 10 | AE17: 13 | AF17: 8 | AG17: 15 | AH17: 14 | AI17: 16 | AJ17: 10 | AK17: 22 | AL17: 9 | AM17: 15 | AN17: 515
B18: MATRONA /ÓN | C18: 6111 | D18: 1514 | E18: 4602 | F18: 5 | G18: 6 | H18: 12 | I18: 5 | J18: 6 | K18: 25 | L18: 256 | M18: 646 | N18: 352 | O18: 952 | P18: 235 | Q18: 765 | R18: 152 | S18: 521 | T18: 117 | U18: 511 | V18: 85 | W18: 290 | X18: 73 | Y18: 317 | Z18: 72 | AA18: 203 | AB18: 58 | AC18: 146 | AD18: 28 | AE18: 81 | AF18: 17 | AG18: 30 | AH18: 22 | AI18: 50 | AJ18: 15 | AK18: 18 | AL18: 9 | AM18: 36 | AN18: 6043
A19: OTROS PROBLEMAS DE SALUD | B19: MÉDICO | C19: 702395 | D19: 189546 | E19: 512849 | F19: 7284 | G19: 6285 | H19: 5629 | I19: 4447 | J19: 5336 | K19: 4714 | L19: 4753 | M19: 7486 | N19: 3569 | O19: 9871 | P19: 3932 | Q19: 14177 | R19: 4288 | S19: 15942 | T19: 4891 | U19: 19518 | V19: 6157 | W19: 25114 | X19: 8782 | Y19: 34001 | Z19: 12752 | AA19: 48059 | AB19: 17384 | AC19: 59067 | AD19: 19228 | AE19: 61711 | AF19: 21424 | AG19: 59362 | AH19: 22769 | AI19: 54103 | AJ19: 19184 | AK19: 41319 | AL19: 22184 | AM19: 47853 | AN19: 690884
B20: ENFERMERA /O | C20: 80633 | D20: 28517 | E20: 52116 | F20: 1647 | G20: 1524 | H20: 626 | I20: 589 | J20: 340 | K20: 321 | L20: 368 | M20: 501 | N20: 351 | O20: 633 | P20: 416 | Q20: 936 | R20: 518 | S20: 1175 | T20: 577 | U20: 1570 | V20: 687 | W20: 1950 | X20: 1092 | Y20: 3053 | Z20: 1751 | AA20: 4596 | AB20: 2682 | AC20: 5158 | AD20: 2933 | AE20: 5939 | AF20: 3420 | AG20: 6490 | AH20: 4055 | AI20: 6277 | AJ20: 3149 | AK20: 4987 | AL20: 3904 | AM20: 6417 | AN20: 78691
B21: MATRONA /ÓN | C21: 13505 | D21: 1261 | E21: 12244 | F21: 620 | G21: 741 | H21: 38 | I21: 73 | J21: 57 | K21: 191 | L21: 32 | M21: 653 | N21: 29 | O21: 857 | P21: 35 | Q21: 1105 | R21: 28 | S21: 910 | T21: 34 | U21: 897 | V21: 35 | W21: 874 | X21: 40 | Y21: 942 | Z21: 45 | AA21: 1049 | AB21: 51 | AC21: 1112 | AD21: 61 | AE21: 1093 | AF21: 49 | AG21: 801 | AH21: 42 | AI21: 566 | AJ21: 25 | AK21: 330 | AL21: 40 | AM21: 212 | AN21: 13399
B22: NUTRICIONISTA | C22: 139925 | D22: 49069 | E22: 90856 | F22: 23914 | G22: 23005 | H22: 6517 | I22: 6740 | J22: 2658 | K22: 3224 | L22: 1053 | M22: 4204 | N22: 579 | O22: 4752 | P22: 701 | Q22: 5568 | R22: 716 | S22: 4808 | T22: 680 | U22: 4295 | V22: 747 | W22: 3723 | X22: 878 | Y22: 4162 | Z22: 1271 | AA22: 5107 | AB22: 1474 | AC22: 4868 | AD22: 1536 | AE22: 4307 | AF22: 1773 | AG22: 3775 | AH22: 1808 | AI22: 3269 | AJ22: 1325 | AK22: 2344 | AL22: 1439 | AM22: 2704 | AN22: 137375
B23: TÉCNICO PARAMÉDICO | C23: 61052 | D23: 25947 | E23: 35105 | F23: 1516 | G23: 1485 | H23: 991 | I23: 1059 | J23: 950 | K23: 1019 | L23: 660 | M23: 1307 | N23: 748 | O23: 1365 | P23: 940 | Q23: 1761 | R23: 977 | S23: 1798 | T23: 1014 | U23: 1888 | V23: 1170 | W23: 2253 | X23: 1549 | Y23: 2497 | Z23: 1973 | AA23: 3031 | AB23: 2100 | AC23: 2763 | AD23: 1998 | AE23: 2839 | AF23: 2259 | AG23: 2676 | AH23: 2493 | AI23: 2410 | AJ23: 2027 | AK23: 2241 | AL23: 2582 | AM23: 2713 | AN23: 60226
A24: NIÑOS CON NECESIDADES ESPECIALES | B24: MÉDICO | C24: 1211 | D24: 734 | E24: 477 | F24: 444 | G24: 299 | H24: 176 | I24: 96 | J24: 77 | K24: 41 | L24: 29 | M24: 24 | N24: 8 | O24: 17 | P24: 0 | Q24: 0 | R24: 0 | S24: 0 | T24: 0 | U24: 15 | V24: 0 | W24: 0 | X24: 0 | Y24: 0 | Z24: 0 | AA24: 0 | AB24: 0 | AC24: 0 | AD24: 0 | AE24: 0 | AF24: 0 | AG24: 0 | AH24: 0 | AI24: 0 | AJ24: 0 | AK24: 0 | AL24: 0 | AM24: 0 | AN24: 1039
B25: ENFERMERA /O | C25: 2878 | D25: 1576 | E25: 1302 | F25: 1259 | G25: 1086 | H25: 245 | I25: 147 | J25: 53 | K25: 33 | L25: 9 | M25: 19 | N25: 10 | O25: 17 | P25: 0 | Q25: 0 | R25: 0 | S25: 0 | T25: 0 | U25: 15 | V25: 0 | W25: 0 | X25: 0 | Y25: 0 | Z25: 0 | AA25: 0 | AB25: 0 | AC25: 0 | AD25: 0 | AE25: 0 | AF25: 0 | AG25: 0 | AH25: 0 | AI25: 0 | AJ25: 0 | AK25: 0 | AL25: 0 | AM25: 0 | AN25: 2698
B26: MATRONA /ÓN | C26: 179 | D26: 43 | E26: 137 | F26: 25 | G26: 20 | H26: 0 | I26: 0 | J26: 7 | K26: 12 | L26: 3 | M26: 42 | N26: 8 | O26: 63 | P26: 0 | Q26: 0 | R26: 0 | S26: 0 | T26: 0 | U26: 15 | V26: 0 | W26: 0 | X26: 0 | Y26: 0 | Z26: 0 | AA26: 0 | AB26: 0 | AC26: 0 | AD26: 0 | AE26: 0 | AF26: 0 | AG26: 0 | AH26: 0 | AI26: 0 | AJ26: 0 | AK26: 0 | AL26: 0 | AM26: 0 | AN26: 175
B27: NUTRICIONISTA | C27: 1936 | D27: 988 | E27: 948 | F27: 763 | G27: 715 | H27: 136 | I27: 104 | J27: 44 | K27: 49 | L27: 35 | M27: 50 | N27: 10 | O27: 30 | P27: 0 | Q27: 0 | R27: 0 | S27: 0 | T27: 0 | U27: 15 | V27: 0 | W27: 0 | X27: 0 | Y27: 0 | Z27: 0 | AA27: 0 | AB27: 0 | AC27: 0 | AD27: 0 | AE27: 0 | AF27: 0 | AG27: 0 | AH27: 0 | AI27: 0 | AJ27: 0 | AK27: 0 | AL27: 0 | AM27: 0 | AN27: 1849
B28: TÉCNICO PARAMÉDICO | C28: 87 | D28: 52 | E28: 35 | F28: 25 | G28: 13 | H28: 16 | I28: 6 | J28: 6 | K28: 4 | L28: 4 | M28: 4 | N28: 1 | O28: 8 | P28: 0 | Q28: 0 | R28: 0 | S28: 0 | T28: 0 | U28: 15 | V28: 0 | W28: 0 | X28: 0 | Y28: 0 | Z28: 0 | AA28: 0 | AB28: 0 | AC28: 0 | AD28: 0 | AE28: 0 | AF28: 0 | AG28: 0 | AH28: 0 | AI28: 0 | AJ28: 0 | AK28: 0 | AL28: 0 | AM28: 0 | AN28: 85
A29: Servicio: Arica
A30: DE SALUD CARDIOVASCULAR | B30: MÉDICO | C30: 19907 | D30: 7288 | E30: 12619 | F30: 0 | G30: 0 | H30: 0 | I30: 0 | J30: 0 | K30: 0 | L30: 10 | M30: 16 | N30: 18 | O30: 36 | P30: 37 | Q30: 31 | R30: 51 | S30: 104 | T30: 81 | U30: 218 | V30: 132 | W30: 360 | X30: 288 | Y30: 646 | Z30: 534 | AA30: 1116 | AB30: 757 | AC30: 1518 | AD30: 920 | AE30: 1622 | AF30: 1148 | AG30: 1939 | AH30: 1346 | AI30: 1958 | AJ30: 1024 | AK30: 1443 | AL30: 942 | AM30: 1612 | AN30: 19841
B31: ENFERMERA /O | C31: 17302 | D31: 6826 | E31: 10476 | F31: 0 | G31: 0 | H31: 0 | I31: 0 | J31: 0 | K31: 0 | L31: 4 | M31: 7 | N31: 14 | O31: 26 | P31: 38 | Q31: 35 | R31: 78 | S31: 111 | T31: 91 | U31: 192 | V31: 169 | W31: 321 | X31: 313 | Y31: 536 | Z31: 530 | AA31: 932 | AB31: 757 | AC31: 1237 | AD31: 880 | AE31: 1286 | AF31: 1038 | AG31: 1567 | AH31: 1147 | AI31: 1513 | AJ31: 840 | AK31: 1123 | AL31: 927 | AM31: 1590 | AN31: 17298
B32: NUTRICIONISTA | C32: 9923 | D32: 3632 | E32: 6291 | F32: 0 | G32: 0 | H32: 0 | I32: 0 | J32: 0 | K32: 0 | L32: 4 | M32: 9 | N32: 9 | O32: 17 | P32: 29 | Q32: 20 | R32: 34 | S32: 57 | T32: 48 | U32: 102 | V32: 86 | W32: 170 | X32: 148 | Y32: 319 | Z32: 265 | AA32: 564 | AB32: 340 | AC32: 746 | AD32: 426 | AE32: 823 | AF32: 550 | AG32: 919 | AH32: 696 | AI32: 1017 | AJ32: 528 | AK32: 732 | AL32: 469 | AM32: 796 | AN32: 9923
B33: TÉCNICO PARAMÉDICO | C33: 303 | D33: 146 | E33: 157 | F33: 0 | G33: 0 | H33: 0 | I33: 0 | J33: 0 | K33: 0 | L33: 0 | M33: 0 | N33: 0 | O33: 0 | P33: 2 | Q33: 0 | R33: 3 | S33: 0 | T33: 1 | U33: 1 | V33: 1 | W33: 9 | X33: 18 | Y33: 7 | Z33: 18 | AA33: 18 | AB33: 35 | AC33: 6 | AD33: 10 | AE33: 8 | AF33: 2 | AG33: 22 | AH33: 22 | AI33: 53 | AJ33: 33 | AK33: 18 | AL33: 1 | AM33: 15 | AN33: 287
A34: DE TUBERCULOSIS | B34: MÉDICO | C34: 402 | D34: 207 | E34: 195 | F34: 9 | G34: 3 | H34: 0 | I34: 0 | J34: 6 | K34: 0 | L34: 0 | M34: 9 | N34: 28 | O34: 13 | P34: 16 | Q34: 20 | R34: 21 | S34: 37 | T34: 18 | U34: 10 | V34: 23 | W34: 14 | X34: 11 | Y34: 12 | Z34: 13 | AA34: 8 | AB34: 17 | AC34: 9 | AD34: 12 | AE34: 24 | AF34: 12 | AG34: 14 | AH34: 6 | AI34: 3 | AJ34: 10 | AK34: 10 | AL34: 5 | AM34: 9 | AN34: 397
B35: ENFERMERA /O | C35: 243 | D35: 141 | E35: 102 | F35: 7 | G35: 0 | H35: 5 | I35: 2 | J35: 2 | K35: 5 | L35: 0 | M35: 3 | N35: 17 | O35: 5 | P35: 11 | Q35: 6 | R35: 12 | S35: 16 | T35: 10 | U35: 3 | V35: 10 | W35: 6 | X35: 13 | Y35: 11 | Z35: 10 | AA35: 11 | AB35: 21 | AC35: 2 | AD35: 9 | AE35: 16 | AF35: 7 | AG35: 4 | AH35: 3 | AI35: 2 | AJ35: 2 | AK35: 4 | AL35: 2 | AM35: 6 | AN35: 243
A36: SEGUIMIENTO AUTOVALENTE CON RIESGO | B36: MÉDICO | C36: 382 | D36: 130 | E36: 252 | F36: 0 | G36: 0 | H36: 0 | I36: 0 | J36: 0 | K36: 0 | L36: 0 | M36: 0 | N36: 0 | O36: 0 | P36: 0 | Q36: 0 | R36: 0 | S36: 0 | T36: 0 | U36: 0 | V36: 0 | W36: 0 | X36: 0 | Y36: 0 | Z36: 0 | AA36: 0 | AB36: 0 | AC36: 0 | AD36: 0 | AE36: 0 | AF36: 19 | AG36: 45 | AH36: 27 | AI36: 76 | AJ36: 33 | AK36: 45 | AL36: 51 | AM36: 86 | AN36: 382
B37: ENFERMERA /O | C37: 223 | D37: 69 | E37: 154 | F37: 0 | G37: 0 | H37: 0 | I37: 0 | J37: 0 | K37: 0 | L37: 0 | M37: 0 | N37: 0 | O37: 0 | P37: 0 | Q37: 0 | R37: 0 | S37: 0 | T37: 0 | U37: 0 | V37: 0 | W37: 0 | X37: 0 | Y37: 0 | Z37: 0 | AA37: 0 | AB37: 0 | AC37: 0 | AD37: 0 | AE37: 0 | AF37: 4 | AG37: 43 | AH37: 29 | AI37: 48 | AJ37: 17 | AK37: 38 | AL37: 19 | AM37: 25 | AN37: 223
A38: SEGUIMIENTO RIESGO DEPENDENCIA | B38: MÉDICO | C38: 101 | D38: 28 | E38: 73 | F38: 0 | G38: 0 | H38: 0 | I38: 0 | J38: 0 | K38: 0 | L38: 0 | M38: 0 | N38: 0 | O38: 0 | P38: 0 | Q38: 0 | R38: 0 | S38: 0 | T38: 0 | U38: 0 | V38: 0 | W38: 0 | X38: 0 | Y38: 0 | Z38: 0 | AA38: 0 | AB38: 0 | AC38: 0 | AD38: 0 | AE38: 0 | AF38: 4 | AG38: 5 | AH38: 3 | AI38: 13 | AJ38: 3 | AK38: 22 | AL38: 18 | AM38: 33 | AN38: 101
B39: ENFERMERA /O | C39: 184 | D39: 69 | E39: 115 | F39: 0 | G39: 0 | H39: 0 | I39: 0 | J39: 0 | K39: 0 | L39: 0 | M39: 0 | N39: 0 | O39: 0 | P39: 0 | Q39: 0 | R39: 0 | S39: 0 | T39: 0 | U39: 0 | V39: 0 | W39: 0 | X39: 0 | Y39: 0 | Z39: 0 | AA39: 0 | AB39: 0 | AC39: 0 | AD39: 0 | AE39: 0 | AF39: 6 | AG39: 17 | AH39: 7 | AI39: 29 | AJ39: 21 | AK39: 23 | AL39: 35 | AM39: 46 | AN39: 184
A40: DE INFECCIÓN TRANSMISIÓN SEXUAL | B40: MÉDICO | C40: 3 | D40: 0 | E40: 3 | F40: 0 | G40: 0 | H40: 0 | I40: 0 | J40: 0 | K40: 0 | L40: 0 | M40: 0 | N40: 0 | O40: 0 | P40: 0 | Q40: 0 | R40: 0 | S40: 0 | T40: 0 | U40: 0 | V40: 0 | W40: 0 | X40: 0 | Y40: 0 | Z40: 0 | AA40: 0 | AB40: 0 | AC40: 0 | AD40: 0 | AE40: 0 | AF40: 0 | AG40: 1 | AH40: 0 | AI40: 1 | AJ40: 0 | AK40: 0 | AL40: 0 | AM40: 1 | AN40: 3
...

Sheet Hoja 21
A1: 2019 [ Enero - Diciembre ]
A2: TIPO DE CONTROL | B2: PROFESIONAL | C2: TOTAL | F2: POR EDAD | AN2: BENEFICIARIOS
F3: 0 - 4 | H3: 45905 | J3: 45944 | L3: 15 - 19 | N3: 20 - 24 | P3: 25 - 29 | R3: 30 - 34 | T3: 35 - 39 | V3: 40 - 44 | X3: 45 - 49 | Z3: 50 - 54 | AB3: 55 - 59 | AD3: 60 - 64 | AF3: 65 - 69 | AH3: 70 - 74 | AJ3: 75 - 79 | AL3: 80 y mas
C4: Ambos Sexos | D4: Hombres | E4: Mujeres | F4: Hombres | G4: Mujeres | H4: Hombres | I4: Mujeres | J4: Hombres | K4: Mujeres | L4: Hombres | M4: Mujeres | N4: Hombres | O4: Mujeres | P4: Hombres | Q4: Mujeres | R4: Hombres | S4: Mujeres | T4: Hombres | U4: Mujeres | V4: Hombres | W4: Mujeres | X4: Hombres | Y4: Mujeres | Z4: Hombres | AA4: Mujeres | AB4: Hombres | AC4: Mujeres | AD4: Hombres | AE4: Mujeres | AF4: Hombres | AG4: Mujeres | AH4: Hombres | AI4: Mujeres | AJ4: Hombres | AK4: Mujeres | AL4: Hombres | AM4: Mujeres
A5: Acumulado Pais
A6: DE SALUD CARDIOVASCULAR | B6: MÉDICO | C6: 5560806 | D6: 2028288 | E6: 3532518 | F6: 0 | G6: 0 | H6: 0 | I6: 0 | J6: 0 | K6: 0 | L6: 3420 | M6: 5474 | N6: 5372 | O6: 11148 | P6: 10606 | Q6: 23416 | R6: 18742 | S6: 40896 | T6: 32792 | U6: 70270 | V6: 58130 | W6: 123432 | X6: 99908 | Y6: 216302 | Z6: 171414 | AA6: 359746 | AB6: 246160 | AC6: 458110 | AD6: 284092 | AE6: 491396 | AF6: 308114 | AG6: 488696 | AH6: 302838 | AI6: 455722 | AJ6: 239446 | AK6: 364440 | AL6: 247242 | AM6: 423482 | AN6: 5514534
B7: ENFERMERA /O | C7: 2552008 | D7: 929456 | E7: 1622538 | F7: 0 | G7: 0 | H7: 0 | I7: 0 | J7: 0 | K7: 0 | L7: 816 | M7: 1124 | N7: 1696 | O7: 3084 | P7: 3412 | Q7: 7360 | R7: 6760 | S7: 14006 | T7: 12328 | U7: 25430 | V7: 22200 | W7: 47916 | X7: 39650 | Y7: 88702 | Z7: 71416 | AA7: 152756 | AB7: 103670 | AC7: 199500 | AD7: 124550 | AE7: 221482 | AF7: 145756 | AG7: 238574 | AH7: 150220 | AI7: 226788 | AJ7: 121274 | AK7: 182332 | AL7: 125710 | AM7: 213494 | AN7: 2527630
B8: NUTRICIONISTA | C8: 2174036 | D8: 747376 | E8: 1426660 | F8: 0 | G8: 0 | H8: 0 | I8: 0 | J8: 0 | K8: 0 | L8: 1460 | M8: 2504 | N8: 2264 | O8: 5538 | P8: 4542 | Q8: 11290 | R8: 7562 | S8: 18468 | T8: 12878 | U8: 31074 | V8: 23062 | W8: 53984 | X8: 38286 | Y8: 93852 | Z8: 65014 | AA8: 152416 | AB8: 90220 | AC8: 190922 | AD8: 103108 | AE8: 200262 | AF8: 112404 | AG8: 197636 | AH8: 112846 | AI8: 182184 | AJ8: 88888 | AK8: 139280 | AL8: 84832 | AM8: 147240 | AN8: 2150452
B9: TÉCNICO PARAMÉDICO | C9: 179088 | D9: 67332 | E9: 111756 | F9: 0 | G9: 0 | H9: 0 | I9: 0 | J9: 0 | K9: 0 | L9: 246 | M9: 314 | N9: 326 | O9: 632 | P9: 572 | Q9: 1150 | R9: 912 | S9: 1884 | T9: 1544 | U9: 2702 | V9: 2044 | W9: 4648 | X9: 3456 | Y9: 7458 | Z9: 5956 | AA9: 12138 | AB9: 7846 | AC9: 14410 | AD9: 8840 | AE9: 14944 | AF9: 9426 | AG9: 15202 | AH9: 10276 | AI9: 13518 | AJ9: 7206 | AK9: 10096 | AL9: 8682 | AM9: 12658 | AN9: 177438
A10: DE TUBERCULOSIS | B10: MÉDICO | C10: 25396 | D10: 14158 | E10: 11238 | F10: 386 | G10: 352 | H10: 384 | I10: 378 | J10: 324 | K10: 256 | L10: 386 | M10: 456 | N10: 1046 | O10: 818 | P10: 1320 | Q10: 1050 | R10: 1278 | S10: 944 | T10: 1230 | U10: 780 | V10: 958 | W10: 704 | X10: 1054 | Y10: 740 | Z10: 1244 | AA10: 866 | AB10: 1086 | AC10: 828 | AD10: 1056 | AE10: 790 | AF10: 758 | AG10: 602 | AH10: 554 | AI10: 588 | AJ10: 534 | AK10: 402 | AL10: 560 | AM10: 684 | AN10: 24424
B11: ENFERMERA /O | C11: 20892 | D11: 11632 | E11: 9260 | F11: 400 | G11: 360 | H11: 316 | I11: 336 | J11: 290 | K11: 418 | L11: 242 | M11: 252 | N11: 766 | O11: 714 | P11: 832 | Q11: 918 | R11: 1332 | S11: 1148 | T11: 1300 | U11: 724 | V11: 730 | W11: 514 | X11: 912 | Y11: 610 | Z11: 1116 | AA11: 728 | AB11: 1046 | AC11: 550 | AD11: 864 | AE11: 304 | AF11: 566 | AG11: 426 | AH11: 320 | AI11: 562 | AJ11: 330 | AK11: 178 | AL11: 270 | AM11: 518 | AN11: 20450
A12: SEGUIMIENTO AUTOVALENTE CON RIESGO | B12: MÉDICO | C12: 6958 | D12: 2932 | E12: 4026 | F12: 0 | G12: 0 | H12: 0 | I12: 0 | J12: 0 | K12: 0 | L12: 0 | M12: 0 | N12: 0 | O12: 0 | P12: 0 | Q12: 0 | R12: 0 | S12: 0 | T12: 0 | U12: 0 | V12: 0 | W12: 0 | X12: 0 | Y12: 0 | Z12: 0 | AA12: 0 | AB12: 0 | AC12: 0 | AD12: 0 | AE12: 0 | AF12: 684 | AG12: 982 | AH12: 822 | AI12: 1046 | AJ12: 640 | AK12: 864 | AL12: 786 | AM12: 1134 | AN12: 6934
B13: ENFERMERA /O | C13: 57010 | D13: 21018 | E13: 36024 | F13: 0 | G13: 0 | H13: 0 | I13: 0 | J13: 0 | K13: 0 | L13: 0 | M13: 0 | N13: 0 | O13: 0 | P13: 0 | Q13: 0 | R13: 0 | S13: 0 | T13: 0 | U13: 0 | V13: 0 | W13: 0 | X13: 0 | Y13: 0 | Z13: 0 | AA13: 0 | AB13: 0 | AC13: 0 | AD13: 0 | AE13: 0 | AF13: 5496 | AG13: 10298 | AH13: 6222 | AI13: 10438 | AJ13: 5112 | AK13: 8188 | AL13: 4156 | AM13: 7100 | AN13: 56536
A14: SEGUIMIENTO RIESGO DEPENDENCIA | B14: MÉDICO | C14: 1808 | D14: 682 | E14: 1126 | F14: 0 | G14: 0 | H14: 0 | I14: 0 | J14: 0 | K14: 0 | L14: 0 | M14: 0 | N14: 0 | O14: 0 | P14: 0 | Q14: 0 | R14: 0 | S14: 0 | T14: 0 | U14: 0 | V14: 0 | W14: 0 | X14: 0 | Y14: 0 | Z14: 0 | AA14: 0 | AB14: 0 | AC14: 0 | AD14: 0 | AE14: 0 | AF14: 110 | AG14: 132 | AH14: 140 | AI14: 184 | AJ14: 110 | AK14: 240 | AL14: 322 | AM14: 570 | AN14: 1796
B15: ENFERMERA /O | C15: 31190 | D15: 11056 | E15: 20134 | F15: 0 | G15: 0 | H15: 0 | I15: 0 | J15: 0 | K15: 0 | L15: 0 | M15: 0 | N15: 0 | O15: 0 | P15: 0 | Q15: 0 | R15: 0 | S15: 0 | T15: 0 | U15: 0 | V15: 0 | W15: 0 | X15: 0 | Y15: 0 | Z15: 0 | AA15: 0 | AB15: 0 | AC15: 0 | AD15: 0 | AE15: 0 | AF15: 1384 | AG15: 2500 | AH15: 2238 | AI15: 3720 | AJ15: 2560 | AK15: 4506 | AL15: 4874 | AM15: 9408 | AN15: 31018
A16: DE INFECCIÓN TRANSMISIÓN SEXUAL | B16: MÉDICO | C16: 5738 | D16: 1990 | E16: 3748 | F16: 58 | G16: 54 | H16: 34 | I16: 38 | J16: 28 | K16: 20 | L16: 96 | M16: 164 | N16: 166 | O16: 304 | P16: 162 | Q16: 234 | R16: 130 | S16: 246 | T16: 112 | U16: 194 | V16: 74 | W16: 180 | X16: 100 | Y16: 212 | Z16: 94 | AA16: 240 | AB16: 194 | AC16: 378 | AD16: 176 | AE16: 354 | AF16: 128 | AG16: 340 | AH16: 186 | AI16: 328 | AJ16: 142 | AK16: 228 | AL16: 110 | AM16: 234 | AN16: 5682
B17: ENFERMERA /O | C17: 1142 | D17: 418 | E17: 724 | F17: 34 | G17: 14 | H17: 4 | I17: 4 | J17: 8 | K17: 14 | L17: 14 | M17: 20 | N17: 2 | O17: 20 | P17: 10 | Q17: 18 | R17: 20 | S17: 20 | T17: 6 | U17: 30 | V17: 24 | W17: 26 | X17: 20 | Y17: 52 | Z17: 28 | AA17: 86 | AB17: 44 | AC17: 74 | AD17: 28 | AE17: 78 | AF17: 54 | AG17: 70 | AH17: 58 | AI17: 72 | AJ17: 30 | AK17: 60 | AL17: 34 | AM17: 66 | AN17: 1132
B18: MATRONA /ÓN | C18: 12438 | D18: 3024 | E18: 9414 | F18: 24 | G18: 82 | H18: 18 | I18: 30 | J18: 18 | K18: 60 | L18: 410 | M18: 1016 | N18: 674 | O18: 1660 | P18: 522 | Q18: 1506 | R18: 278 | S18: 1104 | T18: 172 | U18: 978 | V18: 160 | W18: 676 | X18: 102 | Y18: 614 | Z18: 184 | AA18: 518 | AB18: 102 | AC18: 414 | AD18: 104 | AE18: 228 | AF18: 80 | AG18: 164 | AH18: 68 | AI18: 134 | AJ18: 50 | AK18: 130 | AL18: 58 | AM18: 100 | AN18: 12236
A19: OTROS PROBLEMAS DE SALUD | B19: MÉDICO | C19: 1418278 | D19: 382710 | E19: 1035568 | F19: 15416 | G19: 12468 | H19: 10600 | I19: 8826 | J19: 10206 | K19: 9400 | L19: 9128 | M19: 15408 | N19: 6876 | O19: 19188 | P19: 7712 | Q19: 27516 | R19: 8532 | S19: 32870 | T19: 9546 | U19: 39546 | V19: 11556 | W19: 49384 | X19: 16534 | Y19: 67974 | Z19: 25994 | AA19: 95622 | AB19: 34360 | AC19: 120644 | AD19: 40350 | AE19: 124262 | AF19: 43736 | AG19: 120472 | AH19: 46510 | AI19: 109316 | AJ19: 39754 | AK19: 84386 | AL19: 45914 | AM19: 98272 | AN19: 1402082
B20: ENFERMERA /O | C20: 170578 | D20: 59512 | E20: 111066 | F20: 2488 | G20: 2138 | H20: 990 | I20: 876 | J20: 560 | K20: 542 | L20: 502 | M20: 850 | N20: 798 | O20: 1316 | P20: 732 | Q20: 1834 | R20: 1000 | S20: 2198 | T20: 1178 | U20: 3026 | V20: 1440 | W20: 4042 | X20: 2760 | Y20: 6810 | Z20: 4374 | AA20: 10324 | AB20: 4984 | AC20: 11178 | AD20: 6144 | AE20: 12538 | AF20: 7192 | AG20: 14778 | AH20: 9082 | AI20: 14214 | AJ20: 7058 | AK20: 10546 | AL20: 8230 | AM20: 13856 | AN20: 168012
B21: MATRONA /ÓN | C21: 25018 | D21: 1962 | E21: 23056 | F21: 900 | G21: 900 | H21: 64 | I21: 100 | J21: 114 | K21: 376 | L21: 164 | M21: 1086 | N21: 52 | O21: 1406 | P21: 44 | Q21: 2010 | R21: 68 | S21: 1546 | T21: 96 | U21: 1328 | V21: 34 | W21: 1644 | X21: 40 | Y21: 1886 | Z21: 56 | AA21: 2036 | AB21: 52 | AC21: 2298 | AD21: 58 | AE21: 2282 | AF21: 86 | AG21: 1698 | AH21: 60 | AI21: 1308 | AJ21: 36 | AK21: 742 | AL21: 38 | AM21: 410 | AN21: 24844
B22: NUTRICIONISTA | C22: 229174 | D22: 75734 | E22: 153440 | F22: 30506 | G22: 29254 | H22: 8550 | I22: 9428 | J22: 4066 | K22: 4602 | L22: 1842 | M22: 6428 | N22: 1020 | O22: 7414 | P22: 1164 | Q22: 9352 | R22: 1248 | S22: 8600 | T22: 1248 | U22: 7530 | V22: 1496 | W22: 7366 | X22: 1908 | Y22: 7918 | Z22: 2490 | AA22: 9702 | AB22: 3018 | AC22: 10244 | AD22: 3334 | AE22: 9032 | AF22: 3954 | AG22: 8844 | AH22: 3938 | AI22: 7086 | AJ22: 2786 | AK22: 5108 | AL22: 3166 | AM22: 5532 | AN22: 224632
B23: TÉCNICO PARAMÉDICO | C23: 130332 | D23: 52804 | E23: 77528 | F23: 2342 | G23: 2512 | H23: 1956 | I23: 1950 | J23: 2036 | K23: 2264 | L23: 1506 | M23: 3562 | N23: 1698 | O23: 3822 | P23: 1982 | Q23: 4644 | R23: 1832 | S23: 4594 | T23: 1836 | U23: 4792 | V23: 2330 | W23: 4810 | X23: 3122 | Y23: 5356 | Z23: 4106 | AA23: 6406 | AB23: 4350 | AC23: 6152 | AD23: 4588 | AE23: 5704 | AF23: 4164 | AG23: 5624 | AH23: 5750 | AI23: 4510 | AJ23: 4024 | AK23: 4818 | AL23: 5156 | AM23: 6034 | AN23: 128150
